#include "unity.h"
#include "CException.h"

void setUp(void)
{
}

void tearDown(void)
{
}

void test_BasicTryDoesNothingIfNoThrow(void)
{
  int i;
  CEXCEPTION_T e = 0x5a5a;
  
  Try
  {
    i += 1;
  }
  Catch(e)
  {
    TEST_FAIL("Should Not Enter Catch If Not Thrown")
  }
  
  //verify that e was untouched
  TEST_ASSERT_EQUAL(0x5a5a, e);
}

void test_BasicThrowAndCatch(void)
{
  CEXCEPTION_T e;

  Try
  {
    Throw(0xBEEFBEEF);
    TEST_FAIL("Should Have Thrown An Error")
  }
  Catch(e)
  {
    //verify that e has the right data
    TEST_ASSERT_EQUAL(0xBEEFBEEF, e);
  }

  //verify that e STILL has the right data
  TEST_ASSERT_EQUAL(0xBEEFBEEF, e);
}

void test_BasicThrowAndCatch_WithMiniSyntax(void)
{
  CEXCEPTION_T e;

  //Mini Throw and Catch
  Try
    Throw(0xBEEFBEEF);
  Catch(e)
    TEST_ASSERT_EQUAL(0xBEEFBEEF, e);
  TEST_ASSERT_EQUAL(0xBEEFBEEF, e);
  
  //Mini Passthrough
  Try
    e = 0;
  Catch(e)
    TEST_FAIL("I shouldn't be caught because there was no throw");

  TEST_ASSERT_EQUAL(0, e);
}

void test_VerifyVolatilesSurviveThrowAndCatch(void)
{
  volatile unsigned int VolVal = 0;
  CEXCEPTION_T e;

  Try
  {
    VolVal = 2;
    Throw(0xBEEFBEEF);
    TEST_FAIL("Should Have Thrown An Error")
  }
  Catch(e)
  {
    VolVal += 2;
    TEST_ASSERT_EQUAL(0xBEEFBEEF, e);
  }

  TEST_ASSERT_EQUAL(4, VolVal);
  TEST_ASSERT_EQUAL(0xBEEFBEEF, e);
}

void HappyExceptionThrower(unsigned int ID)
{
  if (ID != 0)
  {
    Throw(ID);
  }
}

void test_ThrowFromASubFunctionAndCatchInRootFunc(void)
{
  volatile  unsigned int ID = 0;
  CEXCEPTION_T e;

  Try
  {

    HappyExceptionThrower(0xBADDF00D);
    TEST_FAIL("Should Have Thrown An Exception");
  }
  Catch(e)
  {
    ID = e;
  }

  //verify that I can pass that value to something else
  TEST_ASSERT_EQUAL(0xBADDF00D, e);
}

void HappyExceptionRethrower(unsigned int ID)
{
  CEXCEPTION_T e;
  
  Try
  {
    Throw(ID);
  }
  Catch(e)
  {
    switch (e)
    {
    case 0xBADDF00D:
      Throw(0xBADDBEEF);
      break;
    default:
      break;
    }
  }
}

void test_ThrowAndCatchFromASubFunctionAndRethrowToCatchInRootFunc(void)
{
  volatile  unsigned int ID = 0;
  CEXCEPTION_T e;
  
  Try
  {
    HappyExceptionRethrower(0xBADDF00D);
    TEST_FAIL("Should Have Rethrown Exception");
  }
  Catch(e)
  {
    ID = 1;
  }

  TEST_ASSERT_EQUAL(0xBADDBEEF, e);
  TEST_ASSERT_EQUAL(1, ID);
}

void test_ThrowAndCatchFromASubFunctionAndNoRethrowToCatchInRootFunc(void)
{
  CEXCEPTION_T e = 3;
  
  Try
  {
    HappyExceptionRethrower(0xBADDBEEF);
  }
  Catch(e)
  {
    TEST_FAIL("Should Not Have Re-thrown Error (it should have already been caught)");
  }
  
  //verify that THIS e is still untouched, even though subfunction was touched
  TEST_ASSERT_EQUAL(3, e);
}

void test_ThrowAnErrorThenEnterATryBlockFromWithinCatch_VerifyThisDoesntCorruptExceptionId(void)
{
  CEXCEPTION_T e;
  
  Try
  {
    HappyExceptionThrower(0xBADDBEEF);
    TEST_FAIL("Should Have Thrown Exception");
  }
  Catch(e)
  {
    TEST_ASSERT_EQUAL(0xBADDBEEF, e);
    HappyExceptionRethrower(0x12345678);
    TEST_ASSERT_EQUAL(0xBADDBEEF, e);
  }
  TEST_ASSERT_EQUAL(0xBADDBEEF, e);
}

void test_ThrowAnErrorThenEnterATryBlockFromWithinCatch_VerifyThatEachExceptionIdIndependent(void)
{
  CEXCEPTION_T e1, e2;
  
  Try
  {
    HappyExceptionThrower(0xBADDBEEF);
    TEST_FAIL("Should Have Thrown Exception");
  }
  Catch(e1)
  {
    TEST_ASSERT_EQUAL(0xBADDBEEF, e1);
    Try
    {
      HappyExceptionThrower(0x12345678);
    }
    Catch(e2)
    {
      TEST_ASSERT_EQUAL(0x12345678, e2);
    }
    TEST_ASSERT_EQUAL(0x12345678, e2);
    TEST_ASSERT_EQUAL(0xBADDBEEF, e1);
  }
  TEST_ASSERT_EQUAL(0x12345678, e2);
  TEST_ASSERT_EQUAL(0xBADDBEEF, e1);
}

void test_CanHaveMultipleTryBlocksInASingleFunction(void)
{
  CEXCEPTION_T e;
  
  Try
  {
    HappyExceptionThrower(0x01234567);
    TEST_FAIL("Should Have Thrown Exception");
  }
  Catch(e)
  {
    TEST_ASSERT_EQUAL(0x01234567, e);
  }

  Try
  {
    HappyExceptionThrower(0xF00D8888);
    TEST_FAIL("Should Have Thrown Exception");
  }
  Catch(e)
  {
    TEST_ASSERT_EQUAL(0xF00D8888, e);
  }
}

void test_CanHaveNestedTryBlocksInASingleFunction_ThrowInside(void)
{
  int i = 0;
  CEXCEPTION_T e;
  
  Try
  {
    Try
    {
      HappyExceptionThrower(0x01234567);
      i = 1;
      TEST_FAIL("Should Have Rethrown Exception");
    }
    Catch(e)
    {
      TEST_ASSERT_EQUAL(0x01234567, e);
    }
  }
  Catch(e)
  {
    TEST_FAIL("Should Have Been Caught By Inside Catch");
  }
}

void test_CanHaveNestedTryBlocksInASingleFunction_ThrowOutside(void)
{
  int i = 0;
  CEXCEPTION_T e;
  
  Try
  {
    Try
    {
      i = 2;
    }
    Catch(e)
    {
      TEST_FAIL("Should NotBe Caught Here");
    }
    HappyExceptionThrower(0x01234567);
    TEST_FAIL("Should Have Rethrown Exception");
  }
  Catch(e)
  {
    TEST_ASSERT_EQUAL(0x01234567, e);
  }
}
